<?xml version="1.0"?>
<!-- Adapted from the p2os package, see http://wiki.ros.org/p2os -->
<!-- Git repository at https://github.com/allenh1/p2os -->

<robot name="pioneer3dx" xmlns:xacro="http://ros.org/wiki/xacro">

  <xacro:include filename="$(find pioneer_description)/urdf/pioneer3dx_wheel.xacro"/>
  <xacro:include filename="$(find pioneer_description)/urdf/materials.xacro" />
  <gazebo>
    <plugin name="gazebo_ros_control" filename="libgazebo_ros_control.so">
        <robotNamespace>/$(arg robot_name)</robotNamespace>
    </plugin>
  </gazebo>
 <xacro:include filename="$(find pioneer_description)/urdf/pioneer_multi.gazebo" />


<!-- Base link to interface with gmapping and move_base -->
  <link name="base_link"/>

<!-- Chassis -->
  <joint name="chassis_joint" type="fixed">
    <origin xyz="-0.045 0 0.148" rpy="0 0 0"/>
    <parent link="base_link"/>
    <child link="chassis"/>
  </joint>

  <link name="chassis">
    <visual name="chassis_visual">
      <origin xyz="0 0 0" rpy="0 0 0"/>
			<geometry name="pioneer_geom">
				<mesh filename="package://pioneer_description/meshes/p3dx_meshes/chassis.stl"/>
			</geometry>
			<material name="ChassisRed"/>
    </visual>
    <collision>
			<origin xyz="0 0 0" rpy="0 0 0"/>
			<geometry>
				<mesh filename="package://pioneer_description/meshes/p3dx_meshes/chassis.stl"/>
				<!--box size="0.43 0.277 0.17"/-->
			</geometry>
		</collision>
		<inertial>
		  <mass value="5.67"/>
		  <inertia ixx="0.07" ixy="0" ixz="0"
		    iyy="0.08" iyz="0"
		    izz="0.10"
		  />
		</inertial>
  </link>

<!-- Top -->
	<joint name="base_top_joint" type="fixed">
		<origin xyz="-0.045 0 0.234" rpy="0 0 0"/>
		<parent link="base_link"/>
		<child link="top_plate"/>
	</joint>

	<link name="top_plate">
		<visual>
			<inertial>
				<mass value="0.01"/>	
				<origin xyz="0 0 0"/>
				<inertia ixx="1" ixy="0" ixz="0"
					 iyy="1" iyz="0"
	 				izz="1"/>
			</inertial>
			<origin xyz="0 0 0" rpy="0 0 0"/>
			<geometry name="top_geom">
				<mesh filename="package://pioneer_description/meshes/p3dx_meshes/top.stl"/>
			</geometry>
			<material name="TopBlack"/>
		</visual>
		<collision>
			<origin xyz="0 0 0" rpy="0 0 0"/>
			<geometry>
				<mesh filename="package://pioneer_description/meshes/p3dx_meshes/top.stl"/>
				<!--box size="0.44 0.38 0.005"/-->
			</geometry>
		</collision>
	</link>

<!-- Swivel -->
	<joint name="base_swivel_joint" type="continuous">
		<origin xyz="-0.185 0 0.055" rpy="0 0 0"/>
		<axis xyz="0 0 1"/>
		<!--<anchor xyz="0 0 0"/>
  	<limit effort="100" velocity="100" k_velocity="0" />
  	<joint_properties damping="0.0" friction="0.0" />-->
		<parent link="base_link"/>
		<child link="swivel"/>
	</joint>
	
	<link name="swivel">
		<inertial>
			<mass value="0.1"/>	
			<origin xyz="0 0 0"/>
			<inertia ixx="0.01" ixy="0" ixz="0"
				 iyy="0.01" iyz="0" izz="0.01"/>
  	</inertial>
	  <visual name="base_visual">
		  <origin xyz="0 0 0" rpy="0 0 0"/>
		  <geometry name="pioneer_geom">
			  <mesh filename="package://pioneer_description/meshes/p3dx_meshes/swivel.stl"/>
		  </geometry>
		  <material name="swivel"/>
	  </visual>
	  <collision>
		  <origin xyz="0 0 0" rpy="0 0 0"/>
		  <geometry>
			  <mesh filename="package://pioneer_description/meshes/p3dx_meshes/swivel.stl"/>
		  </geometry>
	  </collision>
	</link>

<!-- Center Wheel + Hubcap -->
	<link name="center_hubcap">
		<inertial>
			<mass value="0.01"/>	
			<origin xyz="0 0 0"/>
			<inertia ixx="0.012411765597" ixy="-0.000711733678" ixz="0.00050272983"
				 iyy="0.015218160428" iyz="-0.000004273467" izz="0.011763977943"/>
  	 	</inertial>
	  <visual name="base_visual">
		  <origin xyz="0 0 0" rpy="0 0 0"/>
		  <geometry name="pioneer_geom">
			  <mesh filename="package://pioneer_description/meshes/p3dx_meshes/center_hubcap.stl"/>
		  </geometry>
		  <material name="HubcapGrey"/>
	  </visual>
	  <collision>
		  <origin xyz="0 0 0" rpy="0 0 0"/>
		  <geometry>
			  <mesh filename="package://pioneer_description/meshes/p3dx_meshes/center_hubcap.stl"/>
		  </geometry>
	  </collision>
	</link>

	<joint name="swivel_hubcap_joint" type="continuous">
		<origin xyz="-0.026 0 -0.016" rpy="0 0 0"/>
		<axis xyz="0 1 0"/>
		<!--<anchor xyz="0 0 0"/>
    <limit effort="1000" velocity="1000" k_velocity="0" />
    <joint_properties damping="0.0" friction="0.0" />-->
	  <parent link="swivel"/>
		<child link="center_wheel"/>
	</joint>

	<link name="center_wheel">
		<inertial>
			<mass value="0.1"/>	
			<origin xyz="0 0 0"/>
			<inertia ixx="0.012411765597" ixy="-0.000711733678" ixz="0.00050272983"
				 iyy="0.015218160428" iyz="-0.000004273467" izz="0.011763977943"/>
  	 	</inertial>
	  <visual name="base_visual">
		  <origin xyz="0 0 0" rpy="0 0 0"/>
		  <geometry name="pioneer_geom">
			  <mesh filename="package://pioneer_description/meshes/p3dx_meshes/center_wheel.stl"/>
		  </geometry>
		  <material name="WheelBlack"/>
	  </visual>
	  <collision>
		  <origin xyz="0 0 0" rpy="0 0 0"/>
		  <geometry>
		    <mesh filename="package://pioneer_description/meshes/p3dx_meshes/center_wheel.stl"/>
			  <!--<cylinder radius="0.0375" length="0.03"/>-->
		  </geometry>
	  </collision>
	</link>

	<joint name="center_wheel_joint" type="fixed">
		<origin xyz="-0.0035 0 -0.001" rpy="0 0 0"/>
		<parent link="center_wheel"/>
		<child link="center_hubcap"/>
	</joint>
	
	<!-- Left Wheel -->
	<joint name="base_left_wheel_joint" type="continuous">
		<origin xyz="0 0.155 0.093" rpy="0 0 0"/>
		<axis xyz="0 1 0"/>
		<!--<anchor xyz="0 0 0"/>
  	<limit effort="1000" velocity="1000" k_velocity="0" />
  	<joint_properties damping="0.0" friction="0.0" />-->
		<parent link="base_link"/>
		<child link="left_wheel"/>
	</joint>

	<link name="left_wheel">
	  <inertial>
			<mass value="0.1"/>	
			<origin xyz="0 0 0"/>
		  <inertia ixx="0.012411765597" ixy="-0.000711733678" ixz="0.00050272983"
				 iyy="0.015218160428" iyz="-0.000004273467" izz="0.011763977943"/>
  	</inertial>
		<visual>
			<origin xyz="0 0 0" rpy="0 0 0"/>
			<geometry>
				<mesh filename="package://pioneer_description/meshes/p3dx_meshes/left_wheel.stl"/>
			</geometry>
			<material name="WheelBlack"/>
		</visual>
		<collision>
			<origin xyz="0 0 0" rpy="0 0 0"/>
			<geometry>
			  <mesh filename="package://pioneer_description/meshes/p3dx_meshes/left_wheel.stl"/>
				<!--<cylinder radius="0.092" length="0.04"/>-->
			</geometry>
		</collision>
	</link>

	<joint name="left_wheel_hub_joint" type="fixed">
		<origin xyz="0 0 0" rpy="0 0 0"/>
		<parent link="left_wheel"/>
		<child link="left_hub"/>
	</joint>

	<link name="left_hub">
		<visual>
			<origin xyz="0 0 0" rpy="0 0 0"/>
			<geometry>
				<mesh filename="package://pioneer_description/meshes/p3dx_meshes/left_hubcap.stl"/>
			</geometry>
			<material name="HubcapYellow"/>
		</visual>
		<collision>
			<origin xyz="0 0 0" rpy="0 0 0"/>
			<geometry>
				<mesh filename="package://pioneer_description/meshes/p3dx_meshes/left_hubcap.stl"/>
			</geometry>
		</collision>
	</link>
	
	<!-- Right Wheel -->
	<joint name="base_right_wheel_joint" type="continuous">
		<origin xyz="0 -0.155 0.093" rpy="0 0 0"/>
		<axis xyz="0 1 0"/>
		<!--<anchor xyz="0 0 0"/>
  	<limit effort="1000" velocity="1000" k_velocity="0" />
  	<joint_properties damping="0.0" friction="0.0" />-->
		<parent link="base_link"/>
		<child link="right_wheel"/>
	</joint>

	<link name="right_wheel">
  	<inertial>
			<mass value="0.1"/>	
			<origin xyz="0 0 0"/>
			<inertia ixx="0.012411765597" ixy="-0.000711733678" ixz="0.00050272983"
				 iyy="0.015218160428" iyz="-0.000004273467" izz="0.011763977943"/>
  	</inertial>
		<visual>
			<origin xyz="0 0 0" rpy="0 0 0"/>
			<geometry>
				<mesh filename="package://pioneer_description/meshes/p3dx_meshes/right_wheel.stl"/>
			</geometry>
			<material name="WheelBlack"/>
		</visual>
		<collision>
			<origin xyz="0 0 0" rpy="0 0 0"/>
			<geometry>
			  <mesh filename="package://pioneer_description/meshes/p3dx_meshes/right_wheel.stl"/>
				<!--<cylinder radius="0.092" length="0.04"/>-->
			</geometry>
		</collision>
	</link>

	<joint name="right_wheel_hub_joint" type="fixed">
		<origin xyz="0 0 0" rpy="0 0 0"/>
		<parent link="right_wheel"/>
		<child link="right_hub"/>
	</joint>

	<link name="right_hub">
		<visual>
			<origin xyz="0 0 0" rpy="0 0 0"/>
			<geometry>
				<mesh filename="package://pioneer_description/meshes/p3dx_meshes/right_hubcap.stl"/>
			</geometry>
			<material name="HubcapYellow"/>
		</visual>
		<collision>
			<origin xyz="0 0 0" rpy="0 0 0"/>
			<geometry>
				<mesh filename="package://pioneer_description/meshes/p3dx_meshes/right_hubcap.stl"/>
			</geometry>
		</collision>
	</link>

<!-- Front + Back Sonar -->
	<link name="front_sonar">
		<inertial>
			<mass value="0.0001"/>	
			<origin xyz="0 0 0"/>
			<inertia ixx="1" ixy="0" ixz="0"
				 iyy="1" iyz="0" izz="1"/>
		</inertial>
		<visual name="base_visual">
			<origin xyz="0 0 0" rpy="0 0 0"/>
			<geometry name="pioneer_geom">
				<mesh filename="package://pioneer_description/meshes/p3dx_meshes/front_sonar.stl"/>
			</geometry>
			<material name="SonarYellow"/>
		</visual>
		<collision>
			<origin xyz="0 0 0" rpy="0 0 0"/>
			<geometry>
				<mesh filename="package://pioneer_description/meshes/p3dx_meshes/front_sonar.stl"/>
			</geometry>
		</collision>
	</link>

	<joint name="base_front_joint" type="fixed">
		<origin xyz="-0.198 0 0.208" rpy="0 0 0"/>
		<parent link="base_link"/>
		<child link="front_sonar"/>
	</joint>

	<link name="back_sonar">
		<inertial>
			<mass value="0.0001"/>	
			<origin xyz="0 0 0"/>
			<inertia ixx="1" ixy="0" ixz="0"
				 iyy="1" iyz="0" izz="1"/>
		</inertial>
		<visual name="back_sonar_vis">
			<origin xyz="0 0 0" rpy="0 0 0"/>
			<geometry name="pioneer_geom">
				<mesh filename="package://pioneer_description/meshes/p3dx_meshes/back_sonar.stl"/>
			</geometry>
			<material name="SonarYellow"/>
		</visual>
		<collision>
			<origin xyz="0 0 0" rpy="0 0 0"/>
			<geometry>
				<mesh filename="package://pioneer_description/meshes/p3dx_meshes/back_sonar.stl"/>
			</geometry>
		</collision>
	</link>

	<joint name="base_back_joint" type="fixed">
		<origin xyz="0.109 0 0.209" rpy="0 0 0"/>
		<parent link="base_link"/>
		<child link="back_sonar"/>
	</joint>
  
  <joint name="camera_joint" type="fixed">
    <origin xyz="0.21 0 -0.13" rpy="0 1.55 0"/>
    <parent link="top_plate"/>
    <child link="camera_link"/>
  </joint>
  
  <!-- Camera -->
  <link name="camera_link">
    <collision>
      <origin xyz="0 0 0" rpy="0 0 0"/>
      <geometry>
	      <box size="0.05 0.07 0.07"/>
      </geometry>
    </collision>

    <visual>
      <origin xyz="0 0 0" rpy="0 0 0"/>
      <geometry>
      	<box size="0.05 0.07 0.07"/>
      </geometry>
      <material name="CameraGreen"/>
    </visual>

    <inertial>
      <mass value="1e-2" />
      <origin xyz="0 0 0" rpy="0 0 0"/>
      <inertia ixx="1e-6" ixy="0" ixz="0" iyy="1e-6" iyz="0" izz="1e-6" />
    </inertial>
  </link>

<!-- Fork Vertical Base -->
  <joint name="fork_vertical_base_joint" type="fixed">
    <axis xyz="0 1 0"/>
    <origin xyz="0.245 0 0.124" rpy="0 -0.01 0"/>
    <parent link="top_plate"/>
    <child link="fork_vertical_base"/>
  </joint>
  
  <link name="fork_vertical_base">
    <collision>
       <origin xyz="0 0 0" rpy="0 0 0"/>
      <geometry>
	      <box size="0.04 0.05 0.25"/>
      </geometry>
   </collision>

    <visual>
      <origin xyz="0 0 0" rpy="0 0 0"/>
      <geometry>
	      <box size="0.04 0.05 0.25"/>
      </geometry>
     <material name="CameraGreen"/>
    </visual>

    <inertial>
      <mass value="1e-2" />
      <origin xyz="0 0 0" rpy="0 0 0"/>
      <inertia ixx="1e-6" ixy="0" ixz="0" iyy="1e-6" iyz="0" izz="1e-6" />
    </inertial>
  </link>

<!-- Fork Vertical Moving Base -->
  <joint name="fork_moving_base_joint" type="prismatic">
    <axis xyz="0 0 1"/>
    <limit effort="1000.0" lower="-0.15" upper="0.2" velocity="0.3"/> 
    <origin xyz="0.028 0 -0.02" rpy="0 0 0"/>
    <parent link="fork_vertical_base"/>
    <child link="fork_moving_base"/>
  </joint>
  
  <link name="fork_moving_base">
    <collision>
       <origin xyz="0 0 0" rpy="0 0 0"/>
      <geometry>
        <box size="0.018 0.03 0.3"/>
      </geometry>
   </collision>

    <visual>
      <origin xyz="0 0 0" rpy="0 0 0"/>
      <geometry>
	      <box size="0.018 0.03 0.3"/>
      </geometry>
     <material name="CameraGreen"/>
    </visual>

    <inertial>
      <mass value="1e-2" />
      <origin xyz="0 0 0" rpy="0 0 0"/>
      <inertia ixx="1e-6" ixy="0" ixz="0" iyy="1e-6" iyz="0" izz="1e-6" />
    </inertial>
  </link>

<!-- Fork Horizontal base -->
  <joint name="fork_horizontal_base" type="fixed">
    <parent link="fork_moving_base"/>
    <child link="fork_horizontal_base"/>
     <origin xyz="0.002 0 -0.175" rpy="0 0 0"/>
  </joint>
  
  <link name="fork_horizontal_base">
    <collision>
      <origin xyz="0 0 0" rpy="0 0 0"/>
      <geometry>
	      <box size="0.018 0.2 0.05"/>
      </geometry>
   </collision>

    <visual>
      <origin xyz="0 0 0" rpy="0 0 0"/>
      <geometry>
	      <box size="0.018 0.2 0.05"/>
      </geometry>
     <material name="CameraGreen"/>
    </visual>

    <inertial>
      <mass value="1e-2" />
      <origin xyz="0 0 0" rpy="0 0 0"/>
      <inertia ixx="1e-6" ixy="0" ixz="0" iyy="1e-6" iyz="0" izz="1e-6" />
    </inertial>
  </link>


<!-- Fork Left--> 
  <joint name="left_fork_joint" type="fixed">
    <parent link="fork_horizontal_base"/>
    <child link="left_fork"/>
    <origin xyz="0.095 0.075 -0.023" rpy="0 -0.035 0"/>
  </joint>
  
  <link name="left_fork">
  <collision>
       <origin xyz="0 0 0" rpy="0 0 0"/>
      <geometry>
	      <box size="0.20 0.05 0.01"/>
      </geometry>
   </collision>

    <visual>
      <origin xyz="0 0 0" rpy="0 0 0"/>
      <geometry>
	      <box size="0.20 0.05 0.01"/>
      </geometry>
      <material name="CameraGreen"/>
    </visual>

    <inertial>
      <mass value="1e-2" />
      <origin xyz="0 0 0" rpy="0 0 0"/>
      <inertia ixx="1e-6" ixy="0" ixz="0" iyy="1e-6" iyz="0" izz="1e-6" />
    </inertial>
  </link>

<!-- Fork Right -->
  <joint name="right_fork_joint" type="fixed">
    <parent link="fork_horizontal_base"/>
    <child link="right_fork"/>
    <origin xyz="0.095 -0.075 -0.023" rpy="0 -0.035 0"/>
  </joint>
  
  <link name="right_fork">
    <collision>
      <origin xyz="0 0 0" rpy="0 0 0"/>
      <geometry>
	      <box size="0.20 0.05 0.01"/>
      </geometry>
   </collision>

    <visual>
      <origin xyz="0 0 0" rpy="0 0 0"/>
      <geometry>
	      <box size="0.2 0.05 0.01"/>
      </geometry>
      <material name="CameraGreen"/>
    </visual>

    <inertial>
      <mass value="1e-2" />
      <origin xyz="0 0 0" rpy="0 0 0"/>
      <inertia ixx="1e-6" ixy="0" ixz="0" iyy="1e-6" iyz="0" izz="1e-6" />
    </inertial>
  </link>

<!-- Counterweight -->
<!-- inside the chassis over the swivel for stability-->
  <joint name="counterweight_joint" type="fixed">
    <parent link="chassis"/>
    <child link="counterweight_base"/>
    <origin xyz="-0.05 0 -0.025" rpy="0 0 0"/>
  </joint>
  
  <link name="counterweight_base">
    <collision>
      <origin xyz="0 0 0" rpy="0 0 0"/>
      <geometry>
	      <box size="0.05 0.16 0.08"/>
      </geometry>
   </collision>

    <visual>
      <origin xyz="0 0 0" rpy="0 0 0"/>
      <geometry>
	      <box size="0.05 0.16 0.08"/>
      </geometry>
    </visual>

    <inertial>
      <mass value="4" />
      <origin xyz="0 0 0" rpy="0 0 0"/>
      <inertia ixx="0" ixy="0" ixz="0" iyy="0" iyz="0" izz="0" />
    </inertial>
  </link>

  <!-- START: Not sure if I need this, may allow for rosservice calls to gazebo joint manager -->
  <transmission name="fork_trasmission">
    <type>transmission_interface/SimpleTransmission</type>
	    <joint name="fork_moving_base_joint">
      <hardwareInterface>EffortJointInterface</hardwareInterface>
    </joint>
    <actuator name="fork_motor">
      <hardwareInterface>EffortJointInterface</hardwareInterface>
      <mechanicalReduction>1</mechanicalReduction>
    </actuator>
  </transmission>

<transmission name="left_wheel_transmission">
    <type>transmission_interface/SimpleTransmission</type>
    <joint name="base_left_wheel_joint">
      <hardwareInterface>EffortJointInterface</hardwareInterface>
    </joint>
    <actuator name="left_wheel_motor">
      <hardwareInterface>EffortJointInterface</hardwareInterface>
      <mechanicalReduction>1</mechanicalReduction>
    </actuator>
  </transmission>

  <transmission name="right_wheel_transmission">
    <type>transmission_interface/SimpleTransmission</type>
    <joint name="base_right_wheel_joint">
      <hardwareInterface>EffortJointInterface</hardwareInterface>
    </joint>
    <actuator name="right_wheel_motor">
      <hardwareInterface>EffortJointInterface</hardwareInterface>
      <mechanicalReduction>1</mechanicalReduction>
    </actuator>
  </transmission>
  <!-- END: Not sure if I need this -->

</robot>
